<?xml version="1.0" encoding="UTF-8"?>
<!-- Generated by org.testng.reporters.JUnitReportReporter -->
<testsuite hostname="Eugenio-PC" name="insynctive.tests.CreatePersonTest" tests="2" failures="1" timestamp="12 Aug 2015 03:58:11 GMT" time="84,852" errors="0">
  <testcase name="loginTest" time="20,579" classname="insynctive.tests.CreatePersonTest"/>
  <testcase name="createPersonTest" time="64,273" classname="insynctive.tests.CreatePersonTest">
    <failure type="junit.framework.AssertionFailedError">
      <![CDATA[junit.framework.AssertionFailedError
	at junit.framework.Assert.fail(Assert.java:47)
	at junit.framework.Assert.assertTrue(Assert.java:20)
	at junit.framework.Assert.assertTrue(Assert.java:27)
	at insynctive.tests.CreatePersonTest.createPersonTest(CreatePersonTest.java:84)
	at sun.reflect.NativeMethodAccessorImpl.invoke0(Native Method)
	at sun.reflect.NativeMethodAccessorImpl.invoke(Unknown Source)
	at sun.reflect.DelegatingMethodAccessorImpl.invoke(Unknown Source)
	at java.lang.reflect.Method.invoke(Unknown Source)
	at org.testng.internal.MethodInvocationHelper.invokeMethod(MethodInvocationHelper.java:80)
	at org.testng.internal.Invoker.invokeMethod(Invoker.java:673)
	at org.testng.internal.Invoker.invokeTestMethod(Invoker.java:842)
	at org.testng.internal.TestMethodWithDataProviderMethodWorker.call(TestMethodWithDataProviderMethodWorker.java:73)
	at org.testng.internal.TestMethodWithDataProviderMethodWorker.call(TestMethodWithDataProviderMethodWorker.java:14)
	at java.util.concurrent.FutureTask.run(Unknown Source)
	at java.util.concurrent.ThreadPoolExecutor.runWorker(Unknown Source)
	at java.util.concurrent.ThreadPoolExecutor$Worker.run(Unknown Source)
	at java.lang.Thread.run(Unknown Source)
]]>
    </failure>
  </testcase>
</testsuite>
